<?xml version="1.0"?>
<sdf version="1.6">
  <model name="pou">
    <static>false</static>
    <pose>0 0 0.3 0 0 0</pose>
    
    <!-- Base platform for mobility (invisible) -->
    <link name="base_link">
      <pose>0 0 0 0 0 0</pose>
      <inertial>
        <mass>5.0</mass>
        <inertia>
          <ixx>0.1</ixx>
          <iyy>0.1</iyy>
          <izz>0.1</izz>
        </inertia>
      </inertial>
      <collision name="collision">
        <geometry>
          <cylinder>
            <radius>0.15</radius>
            <length>0.05</length>
          </cylinder>
        </geometry>
      </collision>
    </link>

    <!-- Main body (brown rounded shape like Pou) -->
    <link name="body">
      <pose>0 0 0.25 0 0 0</pose>
      <inertial>
        <mass>2.0</mass>
        <inertia>
          <ixx>0.05</ixx>
          <iyy>0.05</iyy>
          <izz>0.05</izz>
        </inertia>
      </inertial>
      <collision name="body_collision">
        <geometry>
          <sphere>
            <radius>0.25</radius>
          </sphere>
        </geometry>
      </collision>
      <visual name="body_visual">
        <geometry>
          <sphere>
            <radius>0.25</radius>
          </sphere>
        </geometry>
        <material>
          <ambient>0.6 0.4 0.2 1</ambient>
          <diffuse>0.7 0.45 0.25 1</diffuse>
          <specular>0.2 0.2 0.2 1</specular>
          <emissive>0.1 0.05 0.02 1</emissive>
        </material>
      </visual>
    </link>

    <!-- Left eye -->
    <link name="left_eye">
      <pose>-0.08 0.15 0.3 0 0 0</pose>
      <inertial>
        <mass>0.01</mass>
        <inertia>
          <ixx>0.001</ixx>
          <iyy>0.001</iyy>
          <izz>0.001</izz>
        </inertia>
      </inertial>
      <visual name="eye_white">
        <geometry>
          <sphere>
            <radius>0.06</radius>
          </sphere>
        </geometry>
        <material>
          <ambient>1 1 1 1</ambient>
          <diffuse>1 1 1 1</diffuse>
        </material>
      </visual>
      <visual name="pupil">
        <pose>0 0.03 0 0 0 0</pose>
        <geometry>
          <sphere>
            <radius>0.03</radius>
          </sphere>
        </geometry>
        <material>
          <ambient>0 0 0 1</ambient>
          <diffuse>0 0 0 1</diffuse>
        </material>
      </visual>
    </link>

    <!-- Right eye -->
    <link name="right_eye">
      <pose>0.08 0.15 0.3 0 0 0</pose>
      <inertial>
        <mass>0.01</mass>
        <inertia>
          <ixx>0.001</ixx>
          <iyy>0.001</iyy>
          <izz>0.001</izz>
        </inertia>
      </inertial>
      <visual name="eye_white">
        <geometry>
          <sphere>
            <radius>0.06</radius>
          </sphere>
        </geometry>
        <material>
          <ambient>1 1 1 1</ambient>
          <diffuse>1 1 1 1</diffuse>
        </material>
      </visual>
      <visual name="pupil">
        <pose>0 0.03 0 0 0 0</pose>
        <geometry>
          <sphere>
            <radius>0.03</radius>
          </sphere>
        </geometry>
        <material>
          <ambient>0 0 0 1</ambient>
          <diffuse>0 0 0 1</diffuse>
        </material>
      </visual>
    </link>

    <!-- Mouth (cute smile) -->
    <link name="mouth">
      <pose>0 0.2 0.2 0 0 0</pose>
      <visual name="mouth_visual">
        <geometry>
          <box>
            <size>0.12 0.02 0.03</size>
          </box>
        </geometry>
        <material>
          <ambient>0.8 0.3 0.3 1</ambient>
          <diffuse>0.9 0.4 0.4 1</diffuse>
        </material>
      </visual>
    </link>

    <!-- Left arm -->
    <link name="left_arm">
      <pose>-0.22 0 0.2 0 0 0</pose>
      <inertial>
        <mass>0.1</mass>
        <inertia>
          <ixx>0.001</ixx>
          <iyy>0.001</iyy>
          <izz>0.001</izz>
        </inertia>
      </inertial>
      <visual name="arm_visual">
        <geometry>
          <cylinder>
            <radius>0.04</radius>
            <length>0.15</length>
          </cylinder>
        </geometry>
        <material>
          <ambient>0.6 0.4 0.2 1</ambient>
          <diffuse>0.7 0.45 0.25 1</diffuse>
        </material>
      </visual>
    </link>

    <!-- Right arm -->
    <link name="right_arm">
      <pose>0.22 0 0.2 0 0 0</pose>
      <inertial>
        <mass>0.1</mass>
        <inertia>
          <ixx>0.001</ixx>
          <iyy>0.001</iyy>
          <izz>0.001</izz>
        </inertia>
      </inertial>
      <visual name="arm_visual">
        <geometry>
          <cylinder>
            <radius>0.04</radius>
            <length>0.15</length>
          </cylinder>
        </geometry>
        <material>
          <ambient>0.6 0.4 0.2 1</ambient>
          <diffuse>0.7 0.45 0.25 1</diffuse>
        </material>
      </visual>
    </link>

    <!-- Joints to connect everything -->
    <joint name="base_to_body" type="fixed">
      <parent>base_link</parent>
      <child>body</child>
    </joint>

    <joint name="body_to_left_eye" type="fixed">
      <parent>body</parent>
      <child>left_eye</child>
    </joint>

    <joint name="body_to_right_eye" type="fixed">
      <parent>body</parent>
      <child>right_eye</child>
    </joint>

    <joint name="body_to_mouth" type="fixed">
      <parent>body</parent>
      <child>mouth</child>
    </joint>

    <joint name="body_to_left_arm" type="revolute">
      <parent>body</parent>
      <child>left_arm</child>
      <axis>
        <xyz>0 0 1</xyz>
        <limit>
          <lower>-0.5</lower>
          <upper>0.5</upper>
        </limit>
      </axis>
    </joint>

    <joint name="body_to_right_arm" type="revolute">
      <parent>body</parent>
      <child>right_arm</child>
      <axis>
        <xyz>0 0 1</xyz>
        <limit>
          <lower>-0.5</lower>
          <upper>0.5</upper>
        </limit>
      </axis>
    </joint>

    <!-- Differential drive plugin for movement -->
    <plugin name="diff_drive" filename="libgazebo_ros_diff_drive.so">
      <ros>
        <namespace>/</namespace>
        <remapping>cmd_vel:=cmd_vel</remapping>
        <remapping>odom:=odom</remapping>
      </ros>

      <update_rate>50</update_rate>
      <left_joint>left_wheel_joint</left_joint>
      <right_joint>right_wheel_joint</right_joint>

      <wheel_separation>0.3</wheel_separation>
      <wheel_diameter>0.1</wheel_diameter>

      <max_wheel_torque>20</max_wheel_torque>
      <max_wheel_acceleration>1.0</max_wheel_acceleration>

      <publish_odom>true</publish_odom>
      <publish_odom_tf>true</publish_odom_tf>
      <publish_wheel_tf>false</publish_wheel_tf>

      <odometry_frame>odom</odometry_frame>
      <robot_base_frame>base_link</robot_base_frame>
    </plugin>

    <!-- Hidden wheels for movement -->
    <link name="left_wheel">
      <pose>-0.15 0 0.05 1.5707 0 0</pose>
      <inertial>
        <mass>0.5</mass>
        <inertia>
          <ixx>0.001</ixx>
          <iyy>0.001</iyy>
          <izz>0.001</izz>
        </inertia>
      </inertial>
      <collision name="collision">
        <geometry>
          <cylinder>
            <radius>0.05</radius>
            <length>0.03</length>
          </cylinder>
        </geometry>
        <surface>
          <friction>
            <ode>
              <mu>1.0</mu>
              <mu2>1.0</mu2>
            </ode>
          </friction>
        </surface>
      </collision>
    </link>

    <link name="right_wheel">
      <pose>0.15 0 0.05 1.5707 0 0</pose>
      <inertial>
        <mass>0.5</mass>
        <inertia>
          <ixx>0.001</ixx>
          <iyy>0.001</iyy>
          <izz>0.001</izz>
        </inertia>
      </inertial>
      <collision name="collision">
        <geometry>
          <cylinder>
            <radius>0.05</radius>
            <length>0.03</length>
          </cylinder>
        </geometry>
        <surface>
          <friction>
            <ode>
              <mu>1.0</mu>
              <mu2>1.0</mu2>
            </ode>
          </friction>
        </surface>
      </collision>
    </link>

    <joint name="left_wheel_joint" type="revolute">
      <parent>base_link</parent>
      <child>left_wheel</child>
      <axis>
        <xyz>0 1 0</xyz>
      </axis>
    </joint>

    <joint name="right_wheel_joint" type="revolute">
      <parent>base_link</parent>
      <child>right_wheel</child>
      <axis>
        <xyz>0 1 0</xyz>
      </axis>
    </joint>

  </model>
</sdf>
